Workbook

Sheet Build
A1: ONCE HUMAN — Build planner
A2: Yellow cells = fill in with the dropdown lists. Stats, HP and sets are computed automatically. The other sheets hold all the data (filterable).
A4: Slot | B4: Item | C4: Mod | D4: Damage / HP | E4: Fire rate | F4: DPS | G4: Item effect
A5: Primary weapon | B5: KVD - Boom! Boom! | C5: Burning Wrath <Deviant Energy> | D5: =IF(B5="","",INDEX(Weapons!$E$2:$E$133,MATCH(B5,Weapons!$A$2:$A$133,0))) | E5: =IF(B5="","",INDEX(Weapons!$F$2:$F$133,MATCH(B5,Weapons!$A$2:$A$133,0))) | F5: =IF(B5="","",INDEX(Weapons!$G$2:$G$133,MATCH(B5,Weapons!$A$2:$A$133,0))) | G5: =IF(B5="","",INDEX(Weapons!$O$2:$O$133,MATCH(B5,Weapons!$A$2:$A$133,0))&"")
A6: Secondary weapon | B6: Recurve Crossbow | C6: Vulnerability Amplifier <Precision> | D6: =IF(B6="","",INDEX(Weapons!$E$2:$E$133,MATCH(B6,Weapons!$A$2:$A$133,0))) | E6: =IF(B6="","",INDEX(Weapons!$F$2:$F$133,MATCH(B6,Weapons!$A$2:$A$133,0))) | F6: =IF(B6="","",INDEX(Weapons!$G$2:$G$133,MATCH(B6,Weapons!$A$2:$A$133,0))) | G6: =IF(B6="","",INDEX(Weapons!$O$2:$O$133,MATCH(B6,Weapons!$A$2:$A$133,0))&"")
A7: Helmet | C7: Deviation Expert <Deviant Energy> | D7: =IF(B7="","",INDEX(Armor!$E$2:$E$176,MATCH(B7,Armor!$A$2:$A$176,0))) | G7: =IF(B7="","",INDEX(Armor!$B$2:$B$176,MATCH(B7,Armor!$A$2:$A$176,0))&" — "&INDEX(Armor!$G$2:$G$176,MATCH(B7,Armor!$A$2:$A$176,0)))
A8: Mask | B8: Shelterer Mask | C8: Blaze Amplifier <Deviant Energy> | D8: =IF(B8="","",INDEX(Armor!$E$2:$E$176,MATCH(B8,Armor!$A$2:$A$176,0))) | G8: =IF(B8="","",INDEX(Armor!$B$2:$B$176,MATCH(B8,Armor!$A$2:$A$176,0))&" — "&INDEX(Armor!$G$2:$G$176,MATCH(B8,Armor!$A$2:$A$176,0)))
A9: Top | C9: Resist Advantage <Survival> | D9: =IF(B9="","",INDEX(Armor!$E$2:$E$176,MATCH(B9,Armor!$A$2:$A$176,0))) | G9: =IF(B9="","",INDEX(Armor!$B$2:$B$176,MATCH(B9,Armor!$A$2:$A$176,0))&" — "&INDEX(Armor!$G$2:$G$176,MATCH(B9,Armor!$A$2:$A$176,0)))
A10: Gloves | C10: Elemental Overload <Deviant Energy> | D10: =IF(B10="","",INDEX(Armor!$E$2:$E$176,MATCH(B10,Armor!$A$2:$A$176,0))) | G10: =IF(B10="","",INDEX(Armor!$B$2:$B$176,MATCH(B10,Armor!$A$2:$A$176,0))&" — "&INDEX(Armor!$G$2:$G$176,MATCH(B10,Armor!$A$2:$A$176,0)))
A11: Bottoms | B11: Shelterer Pants | C11: Status Amplification <Deviant Energy> | D11: =IF(B11="","",INDEX(Armor!$E$2:$E$176,MATCH(B11,Armor!$A$2:$A$176,0))) | G11: =IF(B11="","",INDEX(Armor!$B$2:$B$176,MATCH(B11,Armor!$A$2:$A$176,0))&" — "&INDEX(Armor!$G$2:$G$176,MATCH(B11,Armor!$A$2:$A$176,0)))
A12: Shoes | C12: Steady Hand <Deviant Energy> | D12: =IF(B12="","",INDEX(Armor!$E$2:$E$176,MATCH(B12,Armor!$A$2:$A$176,0))) | G12: =IF(B12="","",INDEX(Armor!$B$2:$B$176,MATCH(B12,Armor!$A$2:$A$176,0))&" — "&INDEX(Armor!$G$2:$G$176,MATCH(B12,Armor!$A$2:$A$176,0)))
A13: Deviation | B13: Pyro Dino | G13: =IF(B13="","",INDEX(Deviations!$D$2:$D$88,MATCH(B13,Deviations!$A$2:$A$88,0)))
A14: Cradle override | G14: =IF(B14="","",INDEX(Overrides!$C$2:$C$171,MATCH(B14,Overrides!$A$2:$A$171,0)))
A15: Food 1 | G15: =IF(B15="","",INDEX(Food!$E$2:$E$155,MATCH(B15,Food!$A$2:$A$155,0)))
A16: Food 2 | G16: =IF(B16="","",INDEX(Food!$E$2:$E$155,MATCH(B16,Food!$A$2:$A$155,0)))
A18: Equipped mod effects
A19: =IF(C5="","",A5) | B19: =IF(C5="","",C5) | G19: =IF(C5="","",INDEX(Mods!$F$2:$F$819,MATCH(C5,Mods!$A$2:$A$819,0)))
A20: =IF(C6="","",A6) | B20: =IF(C6="","",C6) | G20: =IF(C6="","",INDEX(Mods!$F$2:$F$819,MATCH(C6,Mods!$A$2:$A$819,0)))
A21: =IF(C7="","",A7) | B21: =IF(C7="","",C7) | G21: =IF(C7="","",INDEX(Mods!$F$2:$F$819,MATCH(C7,Mods!$A$2:$A$819,0)))
A22: =IF(C8="","",A8) | B22: =IF(C8="","",C8) | G22: =IF(C8="","",INDEX(Mods!$F$2:$F$819,MATCH(C8,Mods!$A$2:$A$819,0)))
A23: =IF(C9="","",A9) | B23: =IF(C9="","",C9) | G23: =IF(C9="","",INDEX(Mods!$F$2:$F$819,MATCH(C9,Mods!$A$2:$A$819,0)))
A24: =IF(C10="","",A10) | B24: =IF(C10="","",C10) | G24: =IF(C10="","",INDEX(Mods!$F$2:$F$819,MATCH(C10,Mods!$A$2:$A$819,0)))
A25: =IF(C11="","",A11) | B25: =IF(C11="","",C11) | G25: =IF(C11="","",INDEX(Mods!$F$2:$F$819,MATCH(C11,Mods!$A$2:$A$819,0)))
A26: =IF(C12="","",A12) | B26: =IF(C12="","",C12) | G26: =IF(C12="","",INDEX(Mods!$F$2:$F$819,MATCH(C12,Mods!$A$2:$A$819,0)))
A28: Summary
A29: Total armor HP | B29: =SUM(D7:D12)
A30: Combined DPS (2 weapons) | B30: =SUM(F5:F6)
A31: Pieces equipped | B31: =COUNTA(B7:B12)
A33: Sets (pieces worn)
A34: =IF(B7="","",INDEX(Armor!$B$2:$B$176,MATCH(B7,Armor!$A$2:$A$176,0))) | B34: =IF(A34="","",COUNTIF($A$34:$A$39,A34)) | C34: =IF(A34="","",IFERROR(INDEX(Armor!$H$2:$H$176,MATCH(B7,Armor!$A$2:$A$176,0))&"",""))
A35: =IF(B8="","",INDEX(Armor!$B$2:$B$176,MATCH(B8,Armor!$A$2:$A$176,0))) | B35: =IF(A35="","",COUNTIF($A$34:$A$39,A35)) | C35: =IF(A35="","",IFERROR(INDEX(Armor!$H$2:$H$176,MATCH(B8,Armor!$A$2:$A$176,0))&"",""))
A36: =IF(B9="","",INDEX(Armor!$B$2:$B$176,MATCH(B9,Armor!$A$2:$A$176,0))) | B36: =IF(A36="","",COUNTIF($A$34:$A$39,A36)) | C36: =IF(A36="","",IFERROR(INDEX(Armor!$H$2:$H$176,MATCH(B9,Armor!$A$2:$A$176,0))&"",""))
A37: =IF(B10="","",INDEX(Armor!$B$2:$B$176,MATCH(B10,Armor!$A$2:$A$176,0))) | B37: =IF(A37="","",COUNTIF($A$34:$A$39,A37)) | C37: =IF(A37="","",IFERROR(INDEX(Armor!$H$2:$H$176,MATCH(B10,Armor!$A$2:$A$176,0))&"",""))
A38: =IF(B11="","",INDEX(Armor!$B$2:$B$176,MATCH(B11,Armor!$A$2:$A$176,0))) | B38: =IF(A38="","",COUNTIF($A$34:$A$39,A38)) | C38: =IF(A38="","",IFERROR(INDEX(Armor!$H$2:$H$176,MATCH(B11,Armor!$A$2:$A$176,0))&"",""))
A39: =IF(B12="","",INDEX(Armor!$B$2:$B$176,MATCH(B12,Armor!$A$2:$A$176,0))) | B39: =IF(A39="","",COUNTIF($A$34:$A$39,A39)) | C39: =IF(A39="","",IFERROR(INDEX(Armor!$H$2:$H$176,MATCH(B12,Armor!$A$2:$A$176,0))&"",""))
A40: Note: theoretical DPS = damage × fire rate ÷ 60 (no crit or effects). Set name repeated per piece; the number shows how many pieces of that set you wear.

Sheet Weapons
A1: Name | B1: Type | C1: Rarity | D1: Tier | E1: Damage | F1: Fire rate (rpm) | G1: Theoretical DPS | H1: Magazine | I1: Crit rate | J1: Crit DMG | K1: Weakspot DMG | L1: Range | M1: Reload | N1: Ammo | O1: Effect | P1: Crafting recipe | Q1: Bench | R1: Page | S1: Image | T1: Effect name | U1: Mobility | V1: Damage falloff | W1: Compatible overrides | X1: Note
A2: AA12 | B2: Shotgun | C2: Uncommon | D2: 5 | E2: 148 | F2: 180 | G2: 444 | R2: ouvrir | S2: ouvrir
A3: ACS12 - Corrosion | B3: Shotgun | C3: Legendary | D3: 5 | E3: 138 | F3: 180 | G3: 414 | H3: 8 | I3: 8% | J3: 27% | K3: 15% | L3: 7m | M3: 2.4s | N3: Shotgun Ammo | O3: 70% chance to trigger Power Surge with a hit, but will not inflict Power Surge status. Power Surge can deal Crit hit, Power Surge Crit Rate +15%. When Power Surge is triggered, Power Surge Crit DMG +15% for 6s. Effect can stack up to 10 times. Power Surge DMG Factor +15%. | P3: Rifle Receiver I x1, Legendary Pneumatic Action I x1, Fixed Stock I x1, Standard Barrel I x1 | Q3: Weapon Bench | R3: ouvrir | S3: ouvrir | T3: Power Surge | U3: 50 | V3: 7m / 13m | W3: Shotgun Amplify, Precise Shot, Handgun Enhancement, Anti-Void, Anti-Void: Shotgun
A4: ACS12 - Netherworld | B4: Shotgun | C4: Epic | D4: 5 | E4: 124 | F4: 180 | G4: 372 | H4: 8 | I4: 8% | J4: 27% | K4: 15% | L4: 7m | M4: 2.4s | N4: Shotgun Ammo | O4: When all projectiles hit, there is a 50% chance to trigger Fast Gunner. After triggering Fast Gunner 2 times, the next 1 shot will consume an additional 1 bullet and fire an additional 5 projectiles. After reloading when the magazine is empty, the first 12 bullets will have Attack +20%. | R4: ouvrir | S4: ouvrir | U4: 50 | V4: 7m / 13m
A5: ACS12 - Pyroclasm Starter | B5: Shotgun | C5: Legendary | D5: 5 | E5: 138 | F5: 180 | G5: 414 | H5: 8 | I5: 8% | J5: 27% | K5: 15% | L5: 7m | M5: 2.4s | N5: Shotgun Ammo | O5: 27% chance to trigger Burn on hit. 20% chance to generate a Deviant Particle on hit, which can be picked up to enter Charge state. While under Charge upon reloading, replace all ammunition as Dragon's Breath ammo until the next reload. Dragon's Breath: Deals Blaze Elemental Weapon DMG equal to 85% Attack (Burn DMG bonus applies). Upon reloading, expend all Charge to increase Blaze Elemental DMG by 10% until next reload. Each Charge stack expended further increases this by an additional 10%, up to 4 stacks. | P5: Rifle Receiver I x1, Legendary Pneumatic Action I x1, Fixed Stock I x1, Standard Barrel I x1 | Q5: Weapon Bench | R5: ouvrir | S5: ouvrir | T5: Burn | U5: 50 | V5: 7m / 13m | W5: Shotgun Amplify, Precise Shot, Handgun Enhancement, Anti-Void, Anti-Void: Shotgun
A6: AKM | B6: Assault Rifle | C6: Uncommon | D6: 5 | E6: 120 | F6: 600 | G6: 1200 | R6: ouvrir | S6: ouvrir
A7: AUG - Electron Cloud | B7: Assault Rifle | C7: Legendary | D7: 5 | E7: 132 | F7: 720 | G7: 1584 | H7: 40 | I7: 10% | J7: 25% | K7: 60% | L7: 26m | M7: 2.3s | N7: Rifle Ammo | O7: When hitting with a weapon, there is a 30% chance to apply Power Surge to the target. The first weapon hit after reloading creates an electromagnetic status zone with a radius of 4m centered on the target (max 1 at a time) lasting 7s. When triggering Power Surge on a unit withing the zone, 1 electric orb is generated moving in a random direction within the zone. When an electric orb hits an obstacle or an enemy, it bounces, with a single orb bouncing up to 10 times. If it hits an enemy unit, it also deals Shock Elemental DMG of 42% Psi Intensity. Shock Elemental DMG +30%. | R7: ouvrir | U7: 60 | V7: 26m / 73m
A8: AWM | B8: Sniper Rifle | C8: Uncommon | D8: 5 | E8: 850 | F8: 40 | G8: 567 | R8: ouvrir | S8: ouvrir
A9: AWS.338 - Black Panther | B9: Sniper Rifle | C9: Epic | D9: 5 | E9: 1094 | F9: 40 | G9: 729 | H9: 5 | I9: 2% | J9: 26% | K9: 95% | L9: 58m | M9: 3.6s | N9: SR Ammo | O9: After aiming for 3s, trigger Fortress Warfare, cooldown 10s. Attack increases the longer you aim, up to 30%. After triggering Fortress Warfare, gain 3 stacks of Brutal Mayhem and Weakspot DMG +25%. Every shot reduces the effect by 1%. | R9: ouvrir | S9: ouvrir | U9: 44 | V9: 58m / 106m
A10: AWS.338 - Bullseye | B10: Sniper Rifle | C10: Legendary | D10: 5 | E10: 1216 | F10: 40 | G10: 811 | H10: 5 | I10: 2% | J10: 26% | K10: 95% | L10: 58m | M10: 3.6s | N10: SR Ammo | O10: 70% chance to trigger The Bull's Eye with a weakspot hit. After switching weapon, the first hit will trigger The Bull's Eye. With a hit, Weakspot DMG +15% for 10s. Effect can st ack up to 3 times. After defeating an enemy with a weakspot hit, Attack +15% for 20s. | P10: Sniper Rifle Receiver I x1, Legendary Bolt Action I x1, Fixed Stock I x1, Long Barrel I x1 | Q10: Weapon Bench | R10: ouvrir | S10: ouvrir | T10: The Bull's Eye | U10: 44 | V10: 58m / 106m | W10: Sniper Rifle Crit Boost, Speedy Shot, Sniper Rifle Weakspot DMG Boost, Long-Range Enhancement, Anti-Phase
A11: Aurora Fort | B11: LMG | C11: Legendary | D11: 5 | E11: 271 | F11: 700 | G11: 3162 | H11: 90 | L11: 29m | M11: 4.5s | N11: Light Machine Gun Bullet | R11: ouvrir | S11: ouvrir | U11: 33 | V11: 29m / 87m / 30% | W11: LMG Reload Boost, Speedy Shot, Automatic Weapon Enhancement, Anti-Regen, Anti-Coherence
A12: BAR | B12: LMG | C12: Uncommon | D12: 5 | E12: 192 | F12: 400 | G12: 1280 | R12: ouvrir | S12: ouvrir
A13: Baseball Bat | B13: Melee | C13: Rare | D13: 5 | E13: 622 | I13: 5% | J13: 25% | K13: 20% | O13: The first heavy attack that hits a target inflicts Blunt DMG and reduces the target's subsequent DMG dealt by 30% for 15s. Ineffective against bosses and Meta-Humans. | R13: ouvrir | S13: ouvrir
A14: Broken Bottle | B14: Melee | C14: Uncommon | D14: 5 | E14: 430 | R14: ouvrir | S14: ouvrir
A15: Camping Knife | B15: Melee | C15: Rare | D15: 5 | E15: 622 | I15: 5% | J15: 25% | K15: 20% | O15: Melee hits have a 33% chance to inflict additional Melee DMG of 50% Attack. | R15: ouvrir | S15: ouvrir
A16: Compound Bow | B16: Crossbow | C16: Legendary | D16: 5 | E16: 1192 | F16: 90 | G16: 1788 | H16: 1 | I16: 2% | J16: 28% | K16: 70% | L16: 19m | M16: 2.6s | N16: Arrow | O16: Gain Crit Rate +10% and Reload Speed +6 upon hitting a target. This effect stacks up to 3 times and lasts for 6s. Upon defeating a target, gain the maximum number of stacks. At max stacks, enhanced Unstable Bomber is triggered upon hitting a target (can Crit and causes the target to lose balance). Every shot fired increases Unstable Bomber's DMG by 3%, stacking up to 6 times. If a shot misses, existing stacks are halved. Hitting a Weakspot has a 40% chance to automatically reload 1 crossbow bolt. | P16: Copper Ingot x10, Metal Scraps x15, Rusted Part x6, Shabby Fabric x4, Stardust Source x15 | Q16: Weapon Bench | R16: ouvrir | S16: ouvrir | U16: 60 | V16: 19m / 30m | W16: Crossbow DMG Boost, Speedy Shot, Long-Range Enhancement, Anti-Phase, Anti-Coherence: Crossbow
A17: Compound Bow - The Burden of Betrayal | B17: Crossbow | C17: Legendary | D17: 5 | E17: 510 | F17: 65 | G17: 552 | H17: 1 | I17: 5% | J17: 45% | K17: 25% | L17: 19m | M17: 1.8s | N17: Arrow | O17: Attacks always trigger Bounce. Bounce targets +2. Number of Bounces +1 and an addition +1 at full charge. Reload Efficiency +100% When a hit or a Bounce hit lands applies 1 stack of Echo to the target Echo: Max 4 stacks. Displays a highlighted visual effect when at max stacks lasting 15s. At full change, Bounce DMG +20% and Crit Rate +25%. When a Bounce hit lands, deals additional Bounce Weapon DMG equal to Echo stacks x80%. Cooldown per target: 1s. After triggering removes all Echo Stacks from the target. If there are no enemies to Bounce to after a hit, number of Bounces +2. | R17: ouvrir | U17: 58 | V17: 19m / 30m
A18: Critical Pulse | B18: Crossbow | C18: Legendary | D18: 5 | E18: 1192 | F18: 90 | G18: 1788 | H18: 1 | I18: 2% | J18: 28% | K18: 70% | L18: 19m | M18: 2.6s | N18: Arrow | O18: Triggers continous Power Surge on hit, with a 70% chance to generate deviatied particles near the player (pick them up to enter a charged state). Continous Power Surge can trigger every 0.5s within 3s on the current target. Higher stacks shorten the interval (minimum 0.26s), stacking up to 5 times (dealing 60% DMG to the player). While in a charged state, hitting a target consumes one charge to create an orb of lightning: dealing Shock Elemental Status DMG of 75% Psi Intensity to targets within 5m every 0.5s. This damage benefits from Power Surge DMG bonuses and has a 5% chance to generate deviated particles lasting for 3s. Shock Elemental DMG bonus +30%. | P18: Copper Ingot x10, Metal Scraps x15, Rusted Part x6, Shabby Fabric x4, Stardust Source x15 | Q18: Weapon Bench | R18: ouvrir | S18: ouvrir | T18: Power Surge | U18: 60 | V18: 19m / 30m | W18: Crossbow DMG Boost, Speedy Shot, Long-Range Enhancement, Anti-Phase, Anti-Coherence: Crossbow
A19: Crowbar | B19: Melee | C19: Epic | D19: 5 | E19: 630 | R19: ouvrir | S19: ouvrir
A20: DB12 - Backfire | B20: Shotgun | C20: Epic | D20: 5 | E20: 190 | F20: 105 | G20: 332 | H20: 12 | I20: 8% | J20: 28% | K20: 20% | L20: 7m | M20: 0.5s | N20: Shotgun Ammo | O20: Hit the enemy 5 times to trigger Frost Vortex. After hitting the enemies inside the Frost Vortex with your weapon 1 time, the enemy will be Frozen for 3s (cooldown 4s, cannot be frozen again during this time). When hitting Frozen enemies, DMG +60%. | R20: ouvrir | S20: ouvrir | T20: Frost Vortex | U20: 53 | V20: 7m / 13m
A21: DB12 - Raining Cash | B21: Shotgun | C21: Legendary | D21: 5 | E21: 212 | F21: 105 | G21: 371 | H21: 12 | I21: 8% | J21: 28% | K21: 20% | L21: 7m | M21: 0.5s | N21: Shotgun Ammo | O21: Reloading triggers Fortress Warfare, cooldown 10s. The longer Fortress Warfare is maintained, the higher the Attack, up to +40%. While in Fortress Warfare, Crit Rate +30%. While in Fortress Warfare, DMG Reduction +30%. | P21: Bullpup Receiver I x1, Legendary Pump Action I x1, DBSG I (craftable) x1 | Q21: Weapon Bench | R21: ouvrir | S21: ouvrir | T21: Fortress Warfare | U21: 53 | V21: 7m / 13m | W21: Shotgun Amplify, Precise Shot, Handgun Enhancement, Anti-Void, Anti-Void: Shotgun
A22: DBSG | B22: Shotgun | C22: Uncommon | D22: 5 | E22: 190 | F22: 180 | G22: 570 | O22: This weapon doesn't have any unique effects. | R22: ouvrir | S22: ouvrir
A23: DBSG - Doombringer | B23: Shotgun | C23: Legendary | D23: 5 | E23: 238 | F23: 180 | G23: 714 | H23: 2 | I23: 10% | J23: 30% | K23: 25% | L23: 7m | M23: 2.1s | N23: Shotgun Ammo | O23: 30% chance to trigger The Bull's Eye when hitting the enemy. This chance is raised to 80% upon hitting an enemy within 5m. Defeating a marked enemy grants Attack +6 for 60s, up to 5 stacks. After triggering The Bull's Eye, DMG Reduction +5% for 8s, up to 4 stack(s). Crit Rate +30% when hitting marked enemies. | P23: DBSG Receiver I x1, Legendary Pump Action I x1, Fixed Stock I x1, DBSG I (craftable) x1 | Q23: Weapon Bench | R23: ouvrir | S23: ouvrir | T23: The Bull's Eye | U23: 66 | V23: 7m / 13m | W23: Shotgun Amplify, Precise Shot, Handgun Enhancement, Anti-Void, Anti-Void: Shotgun
A24: DBSG - Dual Fury | B24: Shotgun | C24: Epic | D24: 5 | E24: 214 | F24: 180 | G24: 642 | H24: 2 | I24: 10% | J24: 30% | K24: 25% | L24: 7m | M24: 2.1s | N24: Shotgun Ammo | O24: The last shot of each magainze inflicts 1 stack of Burn. If all projectiles hit, inflict an additional 1 stack. After hitting the enemy with all projectiles 4 times, enter a special Burn state where you lose some HP (will not fall below 0)m Attack +20%, and Vulnerability +10% for 8s. Hitting enemies affected by Burn with all projectiles has a 50% chance to refill 1 bullet. | R24: ouvrir | S24: ouvrir | U24: 66 | V24: 7m / 13m
A25: DBSG - Format | B25: Shotgun | C25: Legendary | D25: 5 | E25: 340 | F25: 180 | G25: 1020 | H25: 2 | L25: 7m | M25: 2.1s | N25: Shotgun Ammo | P25: DBSG Receiver I x1, Legendary Pump Action I x1, Fixed Stock I x1, DBSG I (craftable) x1 | Q25: Weapon Bench | R25: ouvrir | S25: ouvrir | U25: 60 | V25: 7m / 13m / 10% | W25: Shotgun Amplify, Precise Shot, Handgun Enhancement, Anti-Void, Anti-Void: Shotgun
A26: DBSG - Old Huntsman | B26: Shotgun | C26: Rare | D26: 5 | E26: 190 | F26: 180 | G26: 570 | H26: 2 | I26: 10% | J26: 30% | K26: 25% | L26: 7m | M26: 2.1s | N26: Shotgun Ammo | O26: 35% chance to trigger The Bull's Eye when hitting a target. DMG +20% to targets affected by The Bull's Eye. | R26: ouvrir | S26: ouvrir | U26: 66 | V26: 7m / 13m
A27: DE .50 | B27: Pistol | C27: Uncommon | D27: 5 | E27: 394 | F27: 190 | G27: 1248 | O27: No special abilites. | R27: ouvrir | S27: ouvrir
A28: DE.50 - Goshawk | B28: Pistol | C28: Rare | D28: 5 | E28: 402 | F28: 190 | G28: 1273 | R28: ouvrir | S28: ouvrir
A29: DE.50 - Jaws | B29: Pistol | C29: Legendary | D29: 5 | E29: 494 | F29: 190 | G29: 1564 | H29: 9 | I29: 6% | J29: 25% | K29: 60% | L29: 20m | M29: 1.8s | N29: Pistol Ammo | O29: Unstable Bomber is triggered every 4 shots. Critical hits count as 1 shots for the above purpose. After hitting a Weakspot, gain Explosion Elemental DMG +30% for 8s. Unstable Bomber can Crit, and has Crit Rate +25%. | P29: Pistol Frame I x1, Legendary Recoil Action I x1, Pistol Slide I x1 | Q29: Weapon Bench | R29: ouvrir | S29: ouvrir | T29: Unstable Bomber | U29: 73 | V29: 20m / 32m | W29: Pistol DMG Boost, Speedy Shot, Handgun Enhancement, Anti-Regen, Anti-Coherence
A30: DE.50 - Wildfire | B30: Pistol | C30: Epic | D30: 5 | E30: 444 | F30: 190 | G30: 1406 | H30: 8 | I30: 6% | J30: 25% | K30: 60% | L30: 20m | M30: 1.8s | N30: Pistol Ammo | O30: 60% chance to trigger The Bull's Eye when hitting a target. There is an 80% chance to spread The Bull's Eye to 1 enemy within a 15m area, Weapon DMG +25% for 10s. When hitting a Weakpoint of marked enemies, Attack +3% for 10s, up to 3 stacks. | R30: ouvrir | S30: ouvrir | T30: The Bull's Eye | U30: 73 | V30: 20m / 32m
A31: DP12 | B31: Shotgun | C31: Uncommon | D31: 5 | E31: 184 | F31: 105 | G31: 322 | R31: ouvrir | S31: ouvrir
A32: EBR-14 - Octopus! Grilled Rings! | B32: Sniper Rifle | C32: Legendary | D32: 5 | E32: 310 | F32: 300 | G32: 1550 | H32: 20 | I32: 5% | J32: 40% | K32: 50% | L32: 51m | M32: 3s | N32: SR Ammo | O32: When the weapon hits, 50% chance to appy Burn to the target. At max stacks, Burn targets generate a fire ring, spreading Burn DMG to enemies within 6 meters at Burn frequency. Burn DMG +75%. Max Burn stacks -3. Crit Rate + 20%. | P32: Sniper Rifle Receiver I x1, Legendary Pneumatic Action I x1, Fixed Stock I x1, Long Barrel I x1 | Q32: Weapon Bench | R32: ouvrir | S32: ouvrir | U32: 50 | V32: 51m / 93m | W32: Sniper Rifle Crit Boost, Speedy Shot, Sniper Rifle Weakspot DMG Boost, Long-Range Enhancement, Anti-Phase
A33: Fate of the Mystic | B33: Pistol | C33: Uncommon | D33: 1 | F33: 190 | G33: 0 | R33: ouvrir | S33: ouvrir
A34: Fine Dagger | B34: Melee | C34: Uncommon | D34: 5 | E34: 495 | R34: ouvrir | S34: ouvrir
A35: Fine Steel Pipe | B35: Melee | C35: Uncommon | D35: 5 | E35: 666 | R35: ouvrir | S35: ouvrir
A36: Flamethrower | B36: Flamethrower | C36: Epic | D36: 5 | E36: 252 | F36: 300 | G36: 1260 | R36: ouvrir | S36: ouvrir
A37: Flare Gun | B37: Pistol | C37: Uncommon | D37: 5 | E37: 40 | F37: 140 | G37: 93 | R37: ouvrir | S37: ouvrir
A38: Frozen Northern Pike | B38: Melee | C38: Epic | D38: 5 | E38: 738 | I38: 5% | J38: 25% | K38: 20% | O38: Impacts and heavy attacks will freeze the primary target and generate a Frost Vortex. This can be triggered once every 4s. Attacking a target with Frost Vortex will recover 5% of lost HP, but consumes 2 additional stamina. | R38: ouvrir | S38: ouvrir
A39: G17 - Cash Only | B39: Pistol | C39: Legendary | D39: 5 | E39: 110 | F39: 720 | G39: 1320 | R39: ouvrir | S39: ouvrir
A40: G17 - Dusty | B40: Pistol | C40: Epic | D40: 5 | E40: 206 | F40: 410 | G40: 1408 | H40: 13 | I40: 8% | J40: 28% | K40: 55% | L40: 13m | M40: 2.1s | N40: Pistol Ammo | O40: 55% chance to trigger Shrapnel when hitting a weakspot. When triggered, Shrapnel no longer ignores already hit parts. Weakspot DMG +15%. | R40: ouvrir | S40: ouvrir | U40: 83 | V40: 13m / 25m
...

Sheet Armor
A1: Name | B1: Set | C1: Slot | D1: Rarity | E1: HP | F1: Pollution resist | G1: Effect | H1: Set bonus | I1: Crafting recipe | J1: Bench | K1: Page | L1: Image
A2: Agent Pants | B2: Agent | C2: Bottoms | D2: Epic | E2: 130 | F2: 21 | H2: 1p : Head DMG Reduction +10.0%. | 2p : Weakspot DMG +10.0%. | 3p : Get Bullet Saver effect with every precise kill, Weakspot DMG +15% for 8s. Effect can stack up to 3 times. | 4p : Increase Reload Speed by 20% after killing an enemy; Fire Rate +10% when killing with a Weakspot hit. Effect removed when reloading or switching weapons. | K2: ouvrir | L2: ouvrir
A3: Agent Gloves | B3: Agent | C3: Gloves | D3: Epic | E3: 81 | F3: 21 | H3: 1p : Head DMG Reduction +10.0%. | 2p : Weakspot DMG +10.0%. | 3p : Get Bullet Saver effect with every precise kill, Weakspot DMG +15% for 8s. Effect can stack up to 3 times. | 4p : Increase Reload Speed by 20% after killing an enemy; Fire Rate +10% when killing with a Weakspot hit. Effect removed when reloading or switching weapons. | K3: ouvrir | L3: ouvrir
A4: Agent Helmet | B4: Agent | C4: Helmet | D4: Epic | E4: 54 | F4: 21 | H4: 1p : Head DMG Reduction +10.0%. | 2p : Weakspot DMG +10.0%. | 3p : Get Bullet Saver effect with every precise kill, Weakspot DMG +15% for 8s. Effect can stack up to 3 times. | 4p : Increase Reload Speed by 20% after killing an enemy; Fire Rate +10% when killing with a Weakspot hit. Effect removed when reloading or switching weapons. | K4: ouvrir | L4: ouvrir
A5: Agent Mask | B5: Agent | C5: Mask | D5: Epic | E5: 27 | F5: 28 | H5: 1p : Head DMG Reduction +10.0%. | 2p : Weakspot DMG +10.0%. | 3p : Get Bullet Saver effect with every precise kill, Weakspot DMG +15% for 8s. Effect can stack up to 3 times. | 4p : Increase Reload Speed by 20% after killing an enemy; Fire Rate +10% when killing with a Weakspot hit. Effect removed when reloading or switching weapons. | K5: ouvrir | L5: ouvrir
A6: Agent Shoes | B6: Agent | C6: Shoes | D6: Epic | E6: 108 | F6: 21 | H6: 1p : Head DMG Reduction +10.0%. | 2p : Weakspot DMG +10.0%. | 3p : Get Bullet Saver effect with every precise kill, Weakspot DMG +15% for 8s. Effect can stack up to 3 times. | 4p : Increase Reload Speed by 20% after killing an enemy; Fire Rate +10% when killing with a Weakspot hit. Effect removed when reloading or switching weapons. | K6: ouvrir | L6: ouvrir
A7: Agent Top | B7: Agent | C7: Top | D7: Epic | E7: 140 | F7: 28 | H7: 1p : Head DMG Reduction +10.0%. | 2p : Weakspot DMG +10.0%. | 3p : Get Bullet Saver effect with every precise kill, Weakspot DMG +15% for 8s. Effect can stack up to 3 times. | 4p : Increase Reload Speed by 20% after killing an enemy; Fire Rate +10% when killing with a Weakspot hit. Effect removed when reloading or switching weapons. | K7: ouvrir | L7: ouvrir
A8: Bastille Pants | B8: Bastille | C8: Bottoms | D8: Legendary | E8: 144 | F8: 21 | H8: 1p : When HP is above 70%, Weapon DMG +10%. | 2p : Reload Speed +20.0%. | 3p : Stay crouched and immobile for 0.5 seconds to enter Bastille state, which grants +40% Weapon DMG. Upon exiting Bastille state, sprinting is disabled for 3 seconds and C stamina consumption is increased by 100%. | 4p : 3s after exiting Bastille state, gain 1 stack of Armor per second, up to 60 stacks. While in Bastille state, each stack of Armor provides a Shield equal to 1% of max HP. If the shield drops to 0 during Bastille state, you gain a 30% Vulnerability effect. | K8: ouvrir | L8: ouvrir
A9: Bastille Gloves | B9: Bastille | C9: Gloves | D9: Legendary | E9: 90 | F9: 21 | H9: 1p : When HP is above 70%, Weapon DMG +10%. | 2p : Reload Speed +20.0%. | 3p : Stay crouched and immobile for 0.5 seconds to enter Bastille state, which grants +40% Weapon DMG. Upon exiting Bastille state, sprinting is disabled for 3 seconds and C stamina consumption is increased by 100%. | 4p : 3s after exiting Bastille state, gain 1 stack of Armor per second, up to 60 stacks. While in Bastille state, each stack of Armor provides a Shield equal to 1% of max HP. If the shield drops to 0 during Bastille state, you gain a 30% Vulnerability effect. | K9: ouvrir | L9: ouvrir
A10: Bastille Helmet | B10: Bastille | C10: Helmet | D10: Legendary | E10: 60 | F10: 21 | H10: 1p : When HP is above 70%, Weapon DMG +10%. | 2p : Reload Speed +20.0%. | 3p : Stay crouched and immobile for 0.5 seconds to enter Bastille state, which grants +40% Weapon DMG. Upon exiting Bastille state, sprinting is disabled for 3 seconds and C stamina consumption is increased by 100%. | 4p : 3s after exiting Bastille state, gain 1 stack of Armor per second, up to 60 stacks. While in Bastille state, each stack of Armor provides a Shield equal to 1% of max HP. If the shield drops to 0 during Bastille state, you gain a 30% Vulnerability effect. | K10: ouvrir | L10: ouvrir
A11: Bastille Mask | B11: Bastille | C11: Mask | D11: Legendary | E11: 30 | F11: 28 | H11: 1p : When HP is above 70%, Weapon DMG +10%. | 2p : Reload Speed +20.0%. | 3p : Stay crouched and immobile for 0.5 seconds to enter Bastille state, which grants +40% Weapon DMG. Upon exiting Bastille state, sprinting is disabled for 3 seconds and C stamina consumption is increased by 100%. | 4p : 3s after exiting Bastille state, gain 1 stack of Armor per second, up to 60 stacks. While in Bastille state, each stack of Armor provides a Shield equal to 1% of max HP. If the shield drops to 0 during Bastille state, you gain a 30% Vulnerability effect. | K11: ouvrir | L11: ouvrir
A12: Bastille Shoes | B12: Bastille | C12: Shoes | D12: Legendary | E12: 120 | F12: 21 | H12: 1p : When HP is above 70%, Weapon DMG +10%. | 2p : Reload Speed +20.0%. | 3p : Stay crouched and immobile for 0.5 seconds to enter Bastille state, which grants +40% Weapon DMG. Upon exiting Bastille state, sprinting is disabled for 3 seconds and C stamina consumption is increased by 100%. | 4p : 3s after exiting Bastille state, gain 1 stack of Armor per second, up to 60 stacks. While in Bastille state, each stack of Armor provides a Shield equal to 1% of max HP. If the shield drops to 0 during Bastille state, you gain a 30% Vulnerability effect. | K12: ouvrir | L12: ouvrir
A13: Bastille Jacket | B13: Bastille | C13: Top | D13: Legendary | E13: 156 | F13: 28 | H13: 1p : When HP is above 70%, Weapon DMG +10%. | 2p : Reload Speed +20.0%. | 3p : Stay crouched and immobile for 0.5 seconds to enter Bastille state, which grants +40% Weapon DMG. Upon exiting Bastille state, sprinting is disabled for 3 seconds and C stamina consumption is increased by 100%. | 4p : 3s after exiting Bastille state, gain 1 stack of Armor per second, up to 60 stacks. While in Bastille state, each stack of Armor provides a Shield equal to 1% of max HP. If the shield drops to 0 during Bastille state, you gain a 30% Vulnerability effect. | K13: ouvrir | L13: ouvrir
... A49: Falcon Jacket | B49: Falcon | C49: Top | D49: Epic | E49: 140 | F49: 28 | H49: 1p : Rolling Stamina cost -20%. | 2p : Crit DMG +12.0%. | 3p : When Stamina is over 90%, increase Crit Rate by 5% and Crit DMG by 20%. | 4p : Max Stamina +25. Recover 30 Stamina instantly with a kill. | K49: ouvrir | L49: ouvrir
A50: Ghost Link Pants | B50: Ghost Link | C50: Bottoms | D50: Legendary | E50: 1770 | F50: 21 | H50: 1p : Increases Crit Rate by 3%. | 2p : Reload Efficiency +15%. | 3p : When dealing Weapon DMG, you gain 1 stack of Sync: Weapon DMG +3%. Stacks up to 10 times. Last 5s. | 4p : When Sync reaches 10 stacks, attacking an enemy applies Overload. Overload: Deals Status DMG equal to 50% of Psi Intensity every second to the target and enemies within 3m. Last 5s. | K50: ouvrir
A51: Ghost Link Gloves | B51: Ghost Link | C51: Gloves | D51: Legendary | E51: 1106 | F51: 21 | H51: 1p : Increases Crit Rate by 3%. | 2p : Reload Efficiency +15%. | 3p : When dealing Weapon DMG, you gain 1 stack of Sync: Weapon DMG +3%. Stacks up to 10 times. Last 5s. | 4p : When Sync reaches 10 stacks, attacking an enemy applies Overload. Overload: Deals Status DMG equal to 50% of Psi Intensity every second to the target and enemies within 3m. Last 5s. | K51: ouvrir
A52: Ghost Link Helmet | B52: Ghost Link | C52: Helmet | D52: Legendary | E52: 738 | F52: 21 | H52: 1p : Increases Crit Rate by 3%. | 2p : Reload Efficiency +15%. | 3p : When dealing Weapon DMG, you gain 1 stack of Sync: Weapon DMG +3%. Stacks up to 10 times. Last 5s. | 4p : When Sync reaches 10 stacks, attacking an enemy applies Overload. Overload: Deals Status DMG equal to 50% of Psi Intensity every second to the target and enemies within 3m. Last 5s. | K52: ouvrir
A53: Ghost Link Mask | B53: Ghost Link | C53: Mask | D53: Legendary | E53: 369 | F53: 28 | H53: 1p : Increases Crit Rate by 3%. | 2p : Reload Efficiency +15%. | 3p : When dealing Weapon DMG, you gain 1 stack of Sync: Weapon DMG +3%. Stacks up to 10 times. Last 5s. | 4p : When Sync reaches 10 stacks, attacking an enemy applies Overload. Overload: Deals Status DMG equal to 50% of Psi Intensity every second to the target and enemies within 3m. Last 5s. | K53: ouvrir
A54: Ghost Link Shoes | B54: Ghost Link | C54: Shoes | D54: Legendary | E54: 1475 | F54: 21 | H54: 1p : Increases Crit Rate by 3%. | 2p : Reload Efficiency +15%. | 3p : When dealing Weapon DMG, you gain 1 stack of Sync: Weapon DMG +3%. Stacks up to 10 times. Last 5s. | 4p : When Sync reaches 10 stacks, attacking an enemy applies Overload. Overload: Deals Status DMG equal to 50% of Psi Intensity every second to the target and enemies within 3m. Last 5s. | K54: ouvrir
A55: Ghost Link Vest | B55: Ghost Link | C55: Top | D55: Legendary | E55: 1918 | F55: 28 | H55: 1p : Increases Crit Rate by 3%. | 2p : Reload Efficiency +15%. | 3p : When dealing Weapon DMG, you gain 1 stack of Sync: Weapon DMG +3%. Stacks up to 10 times. Last 5s. | 4p : When Sync reaches 10 stacks, attacking an enemy applies Overload. Overload: Deals Status DMG equal to 50% of Psi Intensity every second to the target and enemies within 3m. Last 5s. | K55: ouvrir
A56: Gravity Tide Pants | B56: Gravity Tide | C56: Bottoms | D56: Legendary | E56: 144 | F56: 21 | H56: 1p : Jump Height +10%. | 2p : Magazine Capacity Bonus 15%. | 3p : When airborne gain 20% monster DMG Reduction; for every 5 meters moved in the air, gain 1 stack of Upper Hand increasing Weapon and Status DMG by +1,5% up to a maximum of 15 stacks. Loose one stack of Upper Hand every 5s. | 4p : When Upper Hand exceeds 10 stacks, Weapon and Status damage +10%; After moving 30 meters in the air, Upper Hand will stop decaying for 20s. | K56: ouvrir | L56: ouvrir
A57: Gravity Tide Gloves | B57: Gravity Tide | C57: Gloves | D57: Legendary | E57: 90 | F57: 21 | H57: 1p : Jump Height +10%. | 2p : Magazine Capacity Bonus 15%. | 3p : When airborne gain 20% monster DMG Reduction; for every 5 meters moved in the air, gain 1 stack of Upper Hand increasing Weapon and Status DMG by +1,5% up to a maximum of 15 stacks. Loose one stack of Upper Hand every 5s. | 4p : When Upper Hand exceeds 10 stacks, Weapon and Status damage +10%; After moving 30 meters in the air, Upper Hand will stop decaying for 20s. | K57: ouvrir | L57: ouvrir
A58: Gravity Tide Cap | B58: Gravity Tide | C58: Helmet | D58: Legendary | E58: 60 | F58: 21 | H58: 1p : Jump Height +10%. | 2p : Magazine Capacity Bonus 15%. | 3p : When airborne gain 20% monster DMG Reduction; for every 5 meters moved in the air, gain 1 stack of Upper Hand increasing Weapon and Status DMG by +1,5% up to a maximum of 15 stacks. Loose one stack of Upper Hand every 5s. | 4p : When Upper Hand exceeds 10 stacks, Weapon and Status damage +10%; After moving 30 meters in the air, Upper Hand will stop decaying for 20s. | K58: ouvrir | L58: ouvrir
A59: Gravity Tide Facewear | B59: Gravity Tide | C59: Mask | D59: Legendary | E59: 30 | F59: 28 | H59: 1p : Jump Height +10%. | 2p : Magazine Capacity Bonus 15%. | 3p : When airborne gain 20% monster DMG Reduction; for every 5 meters moved in the air, gain 1 stack of Upper Hand increasing Weapon and Status DMG by +1,5% up to a maximum of 15 stacks. Loose one stack of Upper Hand every 5s. | 4p : When Upper Hand exceeds 10 stacks, Weapon and Status damage +10%; After moving 30 meters in the air, Upper Hand will stop decaying for 20s. | K59: ouvrir | L59: ouvrir
A60: Gravity Tide Shoes | B60: Gravity Tide | C60: Shoes | D60: Legendary | E60: 120 | F60: 21 | H60: 1p : Jump Height +10%. | 2p : Magazine Capacity Bonus 15%. | 3p : When airborne gain 20% monster DMG Reduction; for every 5 meters moved in the air, gain 1 stack of Upper Hand increasing Weapon and Status DMG by +1,5% up to a maximum of 15 stacks. Loose one stack of Upper Hand every 5s. | 4p : When Upper Hand exceeds 10 stacks, Weapon and Status damage +10%; After moving 30 meters in the air, Upper Hand will stop decaying for 20s. | K60: ouvrir | L60: ouvrir
A61: Gravity Tide Top | B61: Gravity Tide | C61: Top | D61: Legendary | E61: 156 | F61: 28 | H61: 1p : Jump Height +10%. | 2p : Magazine Capacity Bonus 15%. | 3p : When airborne gain 20% monster DMG Reduction; for every 5 meters moved in the air, gain 1 stack of Upper Hand increasing Weapon and Status DMG by +1,5% up to a maximum of 15 stacks. Loose one stack of Upper Hand every 5s. | 4p : When Upper Hand exceeds 10 stacks, Weapon and Status damage +10%; After moving 30 meters in the air, Upper Hand will stop decaying for 20s. | K61: ouvrir | L61: ouvrir
A62: Heavy Duty Clothing Pants | B62: Heavy Duty | C62: Bottoms | D62: Epic | E62: 130 | F62: 21 | H62: 1p : Max HP +10.0%. | 2p : Element DMG (Blaze, Frost, Shock, Blast) + 8%. | 3p : After killing an enemy, increase Movement Speed by 20% for 2s and Elemental DMG (Blaze, Frost, Shock, Blast) by 40%, decay over 8s. | 4p : Within 5m, each enemy grants you DMG Reduction +4%. Effect can stack up to 4 times. | K62: ouvrir | L62: ouvrir
A63: Heavy Duty Clothing Gloves | B63: Heavy Duty | C63: Gloves | D63: Epic | E63: 81 | F63: 21 | H63: 1p : Max HP +10.0%. | 2p : Element DMG (Blaze, Frost, Shock, Blast) + 8%. | 3p : After killing an enemy, increase Movement Speed by 20% for 2s and Elemental DMG (Blaze, Frost, Shock, Blast) by 40%, decay over 8s. | 4p : Within 5m, each enemy grants you DMG Reduction +4%. Effect can stack up to 4 times. | K63: ouvrir | L63: ouvrir
A64: Heavy Duty Clothing Helmet | B64: Heavy Duty | C64: Helmet | D64: Epic | E64: 54 | F64: 21 | H64: 1p : Max HP +10.0%. | 2p : Element DMG (Blaze, Frost, Shock, Blast) + 8%. | 3p : After killing an enemy, increase Movement Speed by 20% for 2s and Elemental DMG (Blaze, Frost, Shock, Blast) by 40%, decay over 8s. | 4p : Within 5m, each enemy grants you DMG Reduction +4%. Effect can stack up to 4 times. | K64: ouvrir | L64: ouvrir
A65: Heavy Duty Clothing Mask | B65: Heavy Duty | C65: Mask | D65: Epic | E65: 27 | F65: 28 | H65: 1p : Max HP +10.0%. | 2p : Element DMG (Blaze, Frost, Shock, Blast) + 8%. | 3p : After killing an enemy, increase Movement Speed by 20% for 2s and Elemental DMG (Blaze, Frost, Shock, Blast) by 40%, decay over 8s. | 4p : Within 5m, each enemy grants you DMG Reduction +4%. Effect can stack up to 4 times. | K65: ouvrir | L65: ouvrir
A66: Heavy Duty Clothing Boots | B66: Heavy Duty | C66: Shoes | D66: Epic | E66: 108 | F66: 21 | H66: 1p : Max HP +10.0%. | 2p : Element DMG (Blaze, Frost, Shock, Blast) + 8%. | 3p : After killing an enemy, increase Movement Speed by 20% for 2s and Elemental DMG (Blaze, Frost, Shock, Blast) by 40%, decay over 8s. | 4p : Within 5m, each enemy grants you DMG Reduction +4%. Effect can stack up to 4 times. | K66: ouvrir | L66: ouvrir
A67: Heavy Duty Clothing Top | B67: Heavy Duty | C67: Top | D67: Epic | E67: 140 | F67: 28 | H67: 1p : Max HP +10.0%. | 2p : Element DMG (Blaze, Frost, Shock, Blast) + 8%. | 3p : After killing an enemy, increase Movement Speed by 20% for 2s and Elemental DMG (Blaze, Frost, Shock, Blast) by 40%, decay over 8s. | 4p : Within 5m, each enemy grants you DMG Reduction +4%. Effect can stack up to 4 times. | K67: ouvrir | L67: ouvrir
... A73: Lonewolf Jacket | B73: Lonewolf | C73: Top | D73: Legendary | E73: 156 | F73: 28 | H73: 1p : Magazine Capacity +10.0%. | 2p : Crit Rate +5.0%. | 3p : Get 1 stacks of Lone Shadow with every 2 weapon crit hit(s). Lone Shadow: Crit DMG + 6% for 30s. The effect can stack up to 8 times. | 4p : Increase max Lone Shadow stacks to 10. After a kill, Crit Rate +8% for 2s. | K73: ouvrir | L73: ouvrir
A74: Hot Dog Shorts | B74: Pièce unique | C74: Bottoms | D74: Epic | E74: 130 | F74: 21 | G74: Bounces +2 | K74: ouvrir | L74: ouvrir
A75: Overloaded Pants | B75: Pièce unique | C75: Bottoms | D75: Legendary | E75: 144 | F75: 21 | G75: After triggering Power Surge 20 times, the next 6 shots will consume reserve ammo instead and Shock DMG +20%. Cooldown: 4s. Triggering Power Surge during the cooldown does not count toward this effect. | K75: ouvrir | L75: ouvrir
A76: Sharp Blade Pants | B76: Pièce unique | C76: Bottoms | D76: Legendary | E76: 144 | F76: 21 | G76: When Triggering Bounce , additionally trigger 1 more time. | K76: ouvrir | L76: ouvrir
A77: Tattoo Pants | B77: Pièce unique | C77: Bottoms | D77: Legendary | E77: 144 | F77: 21 | G77: Bounce has a 100% chance to bounce again upon a hit, dealing 100% Bounce DMG. | K77: ouvrir | L77: ouvrir
A78: Glide Pants | B78: Pièce unique | C78: Bottoms | D78: Legendary | E78: 1770 | F78: 21 | G78: When not in an Unarmed State , replaces Roll with Slide. After sliding, Reload Efficiency +100% and Movement Speed + 30% for 2s. If you are holding a bow sliding immediately load 1 ammo and additionally increases Draw Speed by 100% for 1.5s. | K78: ouvrir
A79: Prickly Dance Pants | B79: Pièce unique | C79: Bottoms | D79: Legendary | E79: 1770 | F79: 21 | G79: Bounce has a 100% chance to bounce again upon a hit, dealing 100% Bounce DMG. | K79: ouvrir
A80: Test Subject Pants | B80: Pièce unique | C80: Bottoms | D80: Uncommon | E80: 1241 | F80: 21 | K80: ouvrir
...

Sheet Sets
A1: Set | B1: Rarity | C1: Pieces | D1: 1 piece | E1: 2 pieces | F1: 3 pieces | G1: 4 pieces | H1: Piece list
A2: Agent | B2: Epic | C2: 6 | D2: Head DMG Reduction +10.0%. | E2: Weakspot DMG +10.0%. | F2: Get Bullet Saver effect with every precise kill, Weakspot DMG +15% for 8s. Effect can stack up to 3 times. | G2: Increase Reload Speed by 20% after killing an enemy; Fire Rate +10% when killing with a Weakspot hit. Effect removed when reloading or switching weapons. | H2: Agent Gloves, Agent Helmet, Agent Mask, Agent Pants, Agent Shoes, Agent Top
A3: Bastille | B3: Legendary | C3: 6 | D3: When HP is above 70%, Weapon DMG +10%. | E3: Reload Speed +20.0%. | F3: Stay crouched and immobile for 0.5 seconds to enter Bastille state, which grants +40% Weapon DMG. Upon exiting Bastille state, sprinting is disabled for 3 seconds and C stamina consumption is increased by 100%. | G3: 3s after exiting Bastille state, gain 1 stack of Armor per second, up to 60 stacks. While in Bastille state, each stack of Armor provides a Shield equal to 1% of max HP. If the shield drops to 0 during Bastille state, you gain a 30% Vulnerability effect. | H3: Bastille Shoes, Bastille Gloves, Bastille Helmet, Bastille Mask, Bastille Pants, Bastille Jacket
A4: Blackstone | B4: Legendary | C4: 6 | D4: Cold and Heat Resist +2,5. | E4: Upon dealing Elemental DMG, gain 1 stack(s) of Warm Sensation (Elemental DMG +2%) for 2s. Triggers 1 time every 0.5s, up to a maximum of 5 stack(s). | F4: When the temperature is between 10 and 30, you gain the Warm status (Elemental DMG +18%). | G4: At 5 stacks of Warm Sensation, you are considered to be in the Warm status. When the environmental temperature is between 10C and 30C, gain Elemental DMG +7%. | H4: Blackstone Shoes, Blackstone Gloves, Blackstone Helmet, Blackstone Mask, Blackstone Pants, Blackstone Tops
A5: Blackstone (Cold) | B5: Legendary | C5: 6 | D5: Cold Resist +5 | E5: Upon dealing Elemental DMG, gain 1 stack of Warm Sensation (Elemental DMG +2%) for 2s. Triggers once every 0.5s, up to 5 stacks. | F5: When the temperature is below 10°C, gain Cold status (Elemental DMG +10%). For every additional degree below, Elemental DMG +0.5%, up to 20%. | G5: At 5 stacks of Warm Sensation, the environmental temperature drops by 5°C, the Cold status DMG bonus is doubled and its cap raised to 40%. | H5: Blackstone Boots - Cold, Blackstone Gloves - Cold, Blackstone Hood - Cold, Blackstone Mask - Cold, Blackstone Pants - Cold, Blackstone Top - Cold
A6: Blackstone (Heat) | B6: Legendary | C6: 6 | D6: Heat Resist +5 | E6: Upon dealing Elemental DMG, gain 1 stack of Warm Sensation (Elemental DMG +2%) for 2s. Triggers once every 0.5s, up to 5 stacks. | F6: When the temperature is above 30°C, gain Passion status (Elemental DMG +10%). For every additional degree above, Elemental DMG +0.5%, up to 20%. | G6: At 5 stacks of Warm Sensation, the environmental temperature rises by 5°C, the Passion status DMG bonus is doubled and its cap raised to 40%. | H6: Blackstone Boots - Heat, Blackstone Gloves - Heat, Blackstone Hood - Heat, Blackstone Mask - Heat, Blackstone Pants - Heat, Blackstone Top - Heat
A7: Blast | B7: Rare | C7: 6 | D7: Heavy Melee DMG +20%. | E7: Torso DMG Reduction +12.0%. | F7: After killing an enemy with a melee attack. DMG +25% for next melee attack within 5s, Melee Swing Speed +15%. | G7: Melee kill an enemy to instantly recover 30 Stamina and increase Movement Speed by 20% for 2s (cooldown: 3s). | H7: Blast Gloves, Blast Helmet, Blast Mask, Blast Pants, Blast Shoes, Blast Top
A8: Dark Resonance | B8: Legendary | C8: 6 | D8: Using ultimate grants 10% temporary shield for 10 seconds. | E8: When Deviant Power is not full, Weapon and Status DMG +12%. | F8: Fr every 1 Energy consumed, Gun and Status DMG +0,6% up to +30%. | G8: Consumes 30 Deviant Power when using Battle Skill, reduces Cooldown by 50%. | H8: Dark Resonance Gloves, Dark Resonance Helmet, Dark Resonance Mask, Dark Resonance Pants, Dark Resonance Shoes, Dark Resonance Vest
A9: Falcon | B9: Epic | C9: 6 | D9: Rolling Stamina cost -20%. | E9: Crit DMG +12.0%. | F9: When Stamina is over 90%, increase Crit Rate by 5% and Crit DMG by 20%. | G9: Max Stamina +25. Recover 30 Stamina instantly with a kill. | H9: Falcon Helmet, Falcon Gloves, Falcon Jacket, Falcon Mask, Falcon Pants, Falcon Shoes
A10: Ghost Link | B10: Legendary | C10: 6 | D10: Increases Crit Rate by 3%. | E10: Reload Efficiency +15%. | F10: When dealing Weapon DMG, you gain 1 stack of Sync: Weapon DMG +3%. Stacks up to 10 times. Last 5s. | G10: When Sync reaches 10 stacks, attacking an enemy applies Overload. Overload: Deals Status DMG equal to 50% of Psi Intensity every second to the target and enemies within 3m. Last 5s. | H10: Ghost Link Gloves, Ghost Link Helmet, Ghost Link Mask, Ghost Link Pants, Ghost Link Shoes, Ghost Link Vest
A11: Gravity Tide | B11: Legendary | C11: 6 | D11: Jump Height +10%. | E11: Magazine Capacity Bonus 15%. | F11: When airborne gain 20% monster DMG Reduction; for every 5 meters moved in the air, gain 1 stack of Upper Hand increasing Weapon and Status DMG by +1,5% up to a maximum of 15 stacks. Loose one stack of Upper Hand every 5s. | G11: When Upper Hand exceeds 10 stacks, Weapon and Status damage +10%; After moving 30 meters in the air, Upper Hand will stop decaying for 20s. | H11: Gravity Tide Cap, Gravity Tide Facewear, Gravity Tide Gloves, Gravity Tide Pants, Gravity Tide Shoes, Gravity Tide Top
A12: Heavy Duty | B12: Epic | C12: 6 | D12: Max HP +10.0%. | E12: Element DMG (Blaze, Frost, Shock, Blast) + 8%. | F12: After killing an enemy, increase Movement Speed by 20% for 2s and Elemental DMG (Blaze, Frost, Shock, Blast) by 40%, decay over 8s. | G12: Within 5m, each enemy grants you DMG Reduction +4%. Effect can stack up to 4 times. | H12: Heavy Duty Clothing Gloves, Heavy Duty Clothing Helmet, Heavy Duty Clothing Mask, Heavy Duty Clothing Pants, Heavy Duty Clothing Boots, Heavy Duty Clothing Top
A13: Lonewolf | B13: Legendary | C13: 6 | D13: Magazine Capacity +10.0%. | E13: Crit Rate +5.0%. | F13: Get 1 stacks of Lone Shadow with every 2 weapon crit hit(s). Lone Shadow: Crit DMG + 6% for 30s. The effect can stack up to 8 times. | G13: Increase max Lone Shadow stacks to 10. After a kill, Crit Rate +8% for 2s. | H13: Lonewolf Gloves, Lonewolf Hat, Lonewolf Jacket, Lonewolf Mask, Lonewolf Pants, Lonewolf Shoes
... A23: Treacherous Tides | B23: Legendary | C23: 6 | D23: Weapon DMG reduction 10%. | E23: When HP is above 70%, Weapon DMG and Status DMG +12%. | F23: The HP reduction from low Sanity is reduced by 40%. Weapon and Status DMG +10% and further increases as your Sanity drops up to 28% (at 30% Sanity) max. | G23: Generates a shield equal to 20% of max HP when HP is below 40%. Cooldown: 8s. | H23: Treacherous Tides Gloves, Treacherous Tides Helmet, Treacherous Tides Mask, Treacherous Tides Pants, Treacherous Tides Shoes, Treacherous Tides Top

Sheet Mods
A1: Name <Variant> | B1: Name | C1: Category | D1: Slot | E1: Variant | F1: Main effect | G1: Page | H1: Image
A2: Abnormal Increase <Aero> | B2: Abnormal Increase | C2: Armor Mod | D2: Bottoms | E2: Aero | F2: When the magazine is empty, Status DMG +10% for 12s (up to 3 stacks). | G2: ouvrir
A3: Abnormal Increase <Aero Deviant Energy> | B3: Abnormal Increase | C3: Armor Mod | D3: Bottoms | E3: Aero Deviant Energy | F3: When the magazine is empty, Status DMG +10% for 12s (up to 3 stacks). | G3: ouvrir
A4: Abnormal Increase <Deviant Energy> | B4: Abnormal Increase | C4: Armor Mod | D4: Bottoms | E4: Deviant Energy | F4: When the magazine is empty, Status DMG +10% for 12s (up to 3 stacks). | G4: ouvrir
A5: Abnormal Increase <Downstar> | B5: Abnormal Increase | C5: Armor Mod | D5: Bottoms | E5: Downstar | F5: When the magazine is empty, Status DMG +10% for 12s (up to 3 stacks). | G5: ouvrir
A6: Abnormal Increase <Downstar Deviant Energy> | B6: Abnormal Increase | C6: Armor Mod | D6: Bottoms | E6: Downstar Deviant Energy | F6: When the magazine is empty, Status DMG +10% for 12s (up to 3 stacks). | G6: ouvrir
A7: Abnormal Increase <General> | B7: Abnormal Increase | C7: Armor Mod | D7: Bottoms | E7: General | F7: When the magazine is empty, Status DMG +10% for 12s (up to 3 stacks). | G7: ouvrir
A8: Abnormal Increase <Precision> | B8: Abnormal Increase | C8: Armor Mod | D8: Bottoms | E8: Precision | F8: When the magazine is empty, Status DMG +10% for 12s (up to 3 stacks). | G8: ouvrir
A9: Abnormal Increase <Resonance> | B9: Abnormal Increase | C9: Armor Mod | D9: Bottoms | E9: Resonance | F9: When the magazine is empty, Status DMG +10% for 12s (up to 3 stacks). | G9: ouvrir
A10: Abnormal Increase <Resonance Deviant Energy> | B10: Abnormal Increase | C10: Armor Mod | D10: Bottoms | E10: Resonance Deviant Energy | F10: When the magazine is empty, Status DMG +10% for 12s (up to 3 stacks). | G10: ouvrir
A11: Abnormal Increase <Survival> | B11: Abnormal Increase | C11: Armor Mod | D11: Bottoms | E11: Survival | F11: When the magazine is empty, Status DMG +10% for 12s (up to 3 stacks). | G11: ouvrir
A12: Abnormal Increase <Violent> | B12: Abnormal Increase | C12: Armor Mod | D12: Bottoms | E12: Violent | F12: When the magazine is empty, Status DMG +10% for 12s (up to 3 stacks). | G12: ouvrir
A13: Bullet Siphon <Aero> | B13: Bullet Siphon | C13: Armor Mod | D13: Bottoms | E13: Aero | F13: Weapon DMG +5%. Every 5 bullets consumed in the magazine grants +4% Weapon DMG, capped at 20%. | G13: ouvrir
A14: Bullet Siphon <Aero Deviant Energy> | B14: Bullet Siphon | C14: Armor Mod | D14: Bottoms | E14: Aero Deviant Energy | F14: Weapon DMG +5%. Every 5 bullets consumed in the magazine grants +4% Weapon DMG, capped at 20%. | G14: ouvrir
A15: Bullet Siphon <Deviant Energy> | B15: Bullet Siphon | C15: Armor Mod | D15: Bottoms | E15: Deviant Energy | F15: Weapon DMG +5%. Every 5 bullets consumed in the magazine grants +4% Weapon DMG, capped at 20%. | G15: ouvrir | H15: ouvrir
A16: Bullet Siphon <Downstar> | B16: Bullet Siphon | C16: Armor Mod | D16: Bottoms | E16: Downstar | F16: Weapon DMG +5%. Every 5 bullets consumed in the magazine grants +4% Weapon DMG, capped at 20%. | G16: ouvrir | H16: ouvrir
A17: Bullet Siphon <Downstar Deviant Energy> | B17: Bullet Siphon | C17: Armor Mod | D17: Bottoms | E17: Downstar Deviant Energy | F17: Weapon DMG +5%. Every 5 bullets consumed in the magazine grants +4% Weapon DMG, capped at 20%. | G17: ouvrir | H17: ouvrir
A18: Bullet Siphon <General> | B18: Bullet Siphon | C18: Armor Mod | D18: Bottoms | E18: General | F18: Weapon DMG +5%. Every 5 bullets consumed in the magazine grants +4% Weapon DMG, capped at 20%. | G18: ouvrir | H18: ouvrir
A19: Bullet Siphon <Precision> | B19: Bullet Siphon | C19: Armor Mod | D19: Bottoms | E19: Precision | F19: Weapon DMG +5%. Every 5 bullets consumed in the magazine grants +4% Weapon DMG, capped at 20%. | G19: ouvrir | H19: ouvrir
A20: Bullet Siphon <Resonance> | B20: Bullet Siphon | C20: Armor Mod | D20: Bottoms | E20: Resonance | F20: Weapon DMG +5%. Every 5 bullets consumed in the magazine grants +4% Weapon DMG, capped at 20%. | G20: ouvrir | H20: ouvrir
A21: Bullet Siphon <Resonance Deviant Energy> | B21: Bullet Siphon | C21: Armor Mod | D21: Bottoms | E21: Resonance Deviant Energy | F21: Weapon DMG +5%. Every 5 bullets consumed in the magazine grants +4% Weapon DMG, capped at 20%. | G21: ouvrir | H21: ouvrir
A22: Bullet Siphon <Survival> | B22: Bullet Siphon | C22: Armor Mod | D22: Bottoms | E22: Survival | F22: Weapon DMG +5%. Every 5 bullets consumed in the magazine grants +4% Weapon DMG, capped at 20%. | G22: ouvrir | H22: ouvrir
A23: Bullet Siphon <Violent> | B23: Bullet Siphon | C23: Armor Mod | D23: Bottoms | E23: Violent | F23: Weapon DMG +5%. Every 5 bullets consumed in the magazine grants +4% Weapon DMG, capped at 20%. | G23: ouvrir | H23: ouvrir
A24: Critical Surge <Aero> | B24: Critical Surge | C24: Armor Mod | D24: Bottoms | E24: Aero | F24: When the magazine is empty, gain Crit DMG for 12s; the effect can stack independently up to 3 times. | G24: ouvrir
A25: Critical Surge <Aero Deviant Energy> | B25: Critical Surge | C25: Armor Mod | D25: Bottoms | E25: Aero Deviant Energy | F25: When the magazine is empty, gain Crit DMG for 12s; the effect can stack independently up to 3 times. | G25: ouvrir
A26: Critical Surge <Deviant Energy> | B26: Critical Surge | C26: Armor Mod | D26: Bottoms | E26: Deviant Energy | F26: When the magazine is empty, gain Crit DMG for 12s; the effect can stack independently up to 3 times. | G26: ouvrir | H26: ouvrir
A27: Critical Surge <Downstar> | B27: Critical Surge | C27: Armor Mod | D27: Bottoms | E27: Downstar | F27: When the magazine is empty, gain Crit DMG for 12s; the effect can stack independently up to 3 times. | G27: ouvrir | H27: ouvrir
A28: Critical Surge <Downstar Deviant Energy> | B28: Critical Surge | C28: Armor Mod | D28: Bottoms | E28: Downstar Deviant Energy | F28: When the magazine is empty, gain Crit DMG for 12s; the effect can stack independently up to 3 times. | G28: ouvrir | H28: ouvrir
A29: Critical Surge <General> | B29: Critical Surge | C29: Armor Mod | D29: Bottoms | E29: General | F29: When the magazine is empty, gain Crit DMG for 12s; the effect can stack independently up to 3 times. | G29: ouvrir | H29: ouvrir
A30: Critical Surge <Precision> | B30: Critical Surge | C30: Armor Mod | D30: Bottoms | E30: Precision | F30: When the magazine is empty, gain Crit DMG for 12s; the effect can stack independently up to 3 times. | G30: ouvrir | H30: ouvrir
A31: Critical Surge <Resonance> | B31: Critical Surge | C31: Armor Mod | D31: Bottoms | E31: Resonance | F31: When the magazine is empty, gain Crit DMG for 12s; the effect can stack independently up to 3 times. | G31: ouvrir | H31: ouvrir
A32: Critical Surge <Resonance Deviant Energy> | B32: Critical Surge | C32: Armor Mod | D32: Bottoms | E32: Resonance Deviant Energy | F32: When the magazine is empty, gain Crit DMG for 12s; the effect can stack independently up to 3 times. | G32: ouvrir | H32: ouvrir
A33: Critical Surge <Survival> | B33: Critical Surge | C33: Armor Mod | D33: Bottoms | E33: Survival | F33: When the magazine is empty, gain Crit DMG for 12s; the effect can stack independently up to 3 times. | G33: ouvrir | H33: ouvrir
A34: Critical Surge <Violent> | B34: Critical Surge | C34: Armor Mod | D34: Bottoms | E34: Violent | F34: When the magazine is empty, gain Crit DMG for 12s; the effect can stack independently up to 3 times. | G34: ouvrir | H34: ouvrir
A35: Deadshot <Aero> | B35: Deadshot | C35: Armor Mod | D35: Bottoms | E35: Aero | F35: Each Crit Hit by non-melee weapons grants +5% Crit DMG, up to 45%. The effect is removed upon the next reload. | G35: ouvrir
A36: Deadshot <Aero Deviant Energy> | B36: Deadshot | C36: Armor Mod | D36: Bottoms | E36: Aero Deviant Energy | F36: Each Crit Hit by non-melee weapons grants +5% Crit DMG, up to 45%. The effect is removed upon the next reload. | G36: ouvrir
A37: Deadshot <Deviant Energy> | B37: Deadshot | C37: Armor Mod | D37: Bottoms | E37: Deviant Energy | F37: Each Crit Hit by non-melee weapons grants +5% Crit DMG, up to 45%. The effect is removed upon the next reload. | G37: ouvrir | H37: ouvrir
A38: Deadshot <Downstar> | B38: Deadshot | C38: Armor Mod | D38: Bottoms | E38: Downstar | F38: Each Crit Hit by non-melee weapons grants +5% Crit DMG, up to 45%. The effect is removed upon the next reload. | G38: ouvrir | H38: ouvrir
A39: Deadshot <Downstar Deviant Energy> | B39: Deadshot | C39: Armor Mod | D39: Bottoms | E39: Downstar Deviant Energy | F39: Each Crit Hit by non-melee weapons grants +5% Crit DMG, up to 45%. The effect is removed upon the next reload. | G39: ouvrir | H39: ouvrir
A40: Deadshot <General> | B40: Deadshot | C40: Armor Mod | D40: Bottoms | E40: General | F40: Each Crit Hit by non-melee weapons grants +5% Crit DMG, up to 45%. The effect is removed upon the next reload. | G40: ouvrir | H40: ouvrir
...

Sheet Deviations
A1: Name | B1: Type | C1: Rarity | D1: Effect | E1: Where to get | F1: Page | G1: Image
A2: Behemoth | B2: Combat | C2: Rare | D2: A loyal companion for Metas. | F2: ouvrir | G2: ouvrir
A3: Brave George | B3: Combat | C3: Epic | D3: A loyal companion for Metas. | F3: ouvrir | G3: ouvrir
A4: Butterfly's Emissary | B4: Combat | C4: Common | D4: Designated Target: designate a target to attack. Auto Attack: attacks enemies; marks the enemy's Weakspot on hit, making it take +25%/30%/35% extra Weakspot DMG for 5s. | E4: Tutoriel Eve of Evolution, GAIA Research Center Ruins, Silo Alpha | F4: ouvrir | G4: ouvrir
A5: By-The-Wind (PVE) | B5: Combat | C5: Legendary | D5: Gravity Lift (Takes effect after player takes the throw, creating a floating area on the ground.). Combat Assist (Generates a floating zone beneath the player, allowing them to freely float in the air at a fixed height. Player movement speed +20%, jump speed +2, and become immune to fall DMG and stagger.). | E5: Can be obtained by participating in a prime war and opening the reward crate. | F5: ouvrir
A6: By-the-Wind | B6: Combat | C6: Rare | D6: Gravity Lift: creates a floating area on the ground. Combat Assist: floating zone under the player (fixed height), Movement Speed +20%, jump speed +2, immune to fall DMG and stagger. | E6: Prime War | F6: ouvrir | G6: ouvrir
A7: Chaos - Mini Wonder | B7: Combat | C7: Epic | D7: Designated Target: buffs an ally. Bullet Absorption: absorbs bullets within a radius. | E7: Tâche « Other World Traveler » (Lowe) | F7: ouvrir | G7: ouvrir
A8: Chaos Mr. Wish | B8: Combat | C8: Epic | D8: Rapid Fire: bursts at enemies near the crosshair, marking them with The Bull's Eye. Auto Attack. | E8: Silo SIGMA | F8: ouvrir | G8: ouvrir
A9: Chaos Snowsprite | B9: Combat | C9: Epic | D9: Auto Attack: generates Ice Crystals near the target every 3s. Crystals shatter when shot, dealing 37.5% to 87.5% Frost DMG to nearby targets and making them take +18% to +42% Frost DMG. | E9: Tâche « Deviation: Snowsprite » (Lowe) | F9: ouvrir | G9: ouvrir
A10: Chaos Zeno-Purifier | B10: Combat | C10: Epic | D10: Designated Target + Auto Attack: lets the player teleport to the target with melee attacks. | E10: Objectif saisonnier « 200 ennemis en mêlée » ou coffres | F10: ouvrir | G10: ouvrir
A11: Chaosaurus | B11: Combat | C11: Epic | D11: Abilities: Straight-line Burn, Telekinetic Effects. Can participate in combat to breathe fire. | F11: ouvrir | G11: ouvrir
A12: Chuckles | B12: Combat | C12: Rare | D12: A loyal companion for Metas. | F12: ouvrir | G12: ouvrir
A13: Dr. Teddy | B13: Combat | C13: Rare | D13: Remote Healing: throw to heal 50% Max HP instantly and revive a downed target. Intime Healing: 8% Max HP heal per second, revives allies. | E13: Silo THETA | F13: ouvrir | G13: ouvrir
A14: Enchanting Void | B14: Combat | C14: Epic | D14: Midnight Maul: player transforms into a panther for 20s, auto-attacks and increases melee DMG taken by targets. Combat Assist: Movement Speed +10% with a melee weapon, recover 10% Max HP on melee hit. | E14: Silo THETA (énigme des statues) | F14: ouvrir | G14: ouvrir
A15: Enchanting Void (PVE) | B15: Combat | C15: Legendary | D15: Midnight Maul. Combat Assist. | E15: Silo Theta (PVE). | F15: ouvrir
A16: Festering Gel | B16: Combat | C16: Common | D16: Flawless Fortification: knocks back enemies and forms a shelter. Build Fortification: fixed shelter that blocks attacks; allies nearby recover 6% HP and 3% Sanity per second. | E16: Monolith of Greed (Ravenous Hunter), Gaia Cliff Monolith (Treant) | F16: ouvrir | G16: ouvrir
A17: Gazacchio | B17: Combat | C17: Legendary | D17: Works within the territory to guard it, capable of producing a special tactical item to despel shadows. | E17: Can Randomly be Obtained after Defeating Shadow Enemies. Gazocchio Quest ( Whalebone Settlement in Vena Fjord - Lowe). | F17: ouvrir
A18: Grumpy Bulb | B18: Combat | C18: Rare | D18: Garlicify: AoE Status DMG on hit and disrupts aggro for 10s. Autonomous Attack: cannot move, continuously attracts aggro of nearby enemies. | E18: Graine d'oignon mature à la base | F18: ouvrir | G18: ouvrir
